<sdf version='1.7'>
  <world name='default'>
    <model name='botanical_garden'>
      <pose>0 0 0 0 -0 0</pose>
      <static>1</static>
      <link name='body'>
        <collision name='collision'>
          <geometry>
            <mesh>
              <uri>model://botanical_garden_gazebo.dae</uri>
            </mesh>
          </geometry>
          <max_contacts>10</max_contacts>
          <surface>
            <contact>
              <ode/>
            </contact>
            <bounce/>
            <friction>
              <torsional>
                <ode/>
              </torsional>
              <ode/>
            </friction>
          </surface>
        </collision>
        <visual name='visual'>
          <geometry>
            <mesh>
              <uri>model://botanical_garden_gazebo.dae</uri>
            </mesh>
          </geometry>
        </visual>
        <self_collide>0</self_collide>
        <enable_wind>0</enable_wind>
        <kinematic>0</kinematic>
      </link>
    </model>
    <gravity>0 0 -9.8</gravity>
    <magnetic_field>6e-06 2.3e-05 -4.2e-05</magnetic_field>
    <atmosphere type='adiabatic'/>
    <physics type='ode'>
      <max_step_size>0.001</max_step_size>
      <real_time_factor>1</real_time_factor>
      <real_time_update_rate>1000</real_time_update_rate>
    </physics>
    <scene>
      <ambient>0.4 0.4 0.4 1</ambient>
      <background>0.7 0.7 0.7 1</background>
      <shadows>1</shadows>
    </scene>
    <wind/>
    <spherical_coordinates>
      <surface_model>EARTH_WGS84</surface_model>
      <latitude_deg>0</latitude_deg>
      <longitude_deg>0</longitude_deg>
      <elevation>0</elevation>
      <heading_deg>0</heading_deg>
    </spherical_coordinates>
    <model name='pluto'>
      <link name='base_footprint'>
        <inertial>
          <pose>0 0 0.2 0 -0 0</pose>
          <mass>40</mass>
          <inertia>
            <ixx>0.447787</ixx>
            <ixy>0</ixy>
            <ixz>-0.143071</ixz>
            <iyy>1.31521</iyy>
            <iyz>0</iyz>
            <izz>1.42809</izz>
          </inertia>
        </inertial>
        <collision name='base_footprint_fixed_joint_lump__base_link_collision'>
          <pose>0 0 0.2 0 -0.142 0</pose>
          <geometry>
            <mesh>
              <scale>1 1 1</scale>
              <uri>/root/catkin_ws/src/pluto_robot/pluto_description/meshes/pluto_base_collision.stl</uri>
            </mesh>
          </geometry>
          <surface>
            <contact>
              <ode/>
            </contact>
            <friction>
              <ode/>
              <torsional>
                <ode/>
              </torsional>
            </friction>
            <bounce/>
          </surface>
          <max_contacts>10</max_contacts>
        </collision>
        <visual name='base_footprint_fixed_joint_lump__base_link_visual'>
          <pose>0 0 0.2 0 -0.142 0</pose>
          <geometry>
            <mesh>
              <scale>1 1 1</scale>
              <uri>/root/catkin_ws/src/pluto_robot/pluto_description/meshes/pluto_base.stl</uri>
            </mesh>
          </geometry>
          <material>
            <script>
              <name>Gazebo/GreyTransparent</name>
              <uri>file://media/materials/scripts/gazebo.material</uri>
            </script>
          </material>
        </visual>
        <visual name='base_footprint_fixed_joint_lump__imu_center_visual_1'>
          <pose>0.021504 0 0.127312 2.99959 -0 1.5708</pose>
          <geometry>
            <box>
              <size>0.06 0.06 0.02</size>
            </box>
          </geometry>
        </visual>
        <visual name='base_footprint_fixed_joint_lump__velodyne_visual_2'>
          <pose>0.27709 0 0.307396 0 -0.142 0</pose>
          <geometry>
            <cylinder>
              <length>0.1442</length>
              <radius>0.04265</radius>
            </cylinder>
          </geometry>
        </visual>
        <sensor name='velodyne' type='ray'>
          <always_on>1</always_on>
          <update_rate>5</update_rate>
          <visualize>0</visualize>
          <ray>
            <scan>
              <horizontal>
                <samples>360</samples>
                <resolution>1</resolution>
                <min_angle>-3.14159</min_angle>
                <max_angle>3.14159</max_angle>
              </horizontal>
              <vertical>
                <samples>3</samples>
                <resolution>1</resolution>
                <min_angle>-0.43284</min_angle>
                <max_angle>0.0349</max_angle>
              </vertical>
            </scan>
            <range>
              <min>0.22</min>
              <max>50</max>
              <resolution>0.02</resolution>
            </range>
          </ray>
          <plugin name='laser_controller' filename='libgazebo_ros_block_laser.so'>
            <frameName>velodyne</frameName>
            <topicName>velodyne</topicName>
            <gaussianNoise>0.02</gaussianNoise>
            <updateRate>5</updateRate>
            <robotNamespace>/</robotNamespace>
          </plugin>
          <pose>0.264239 0 0.397287 0 -0.142 0</pose>
        </sensor>
        <self_collide>0</self_collide>
        <enable_wind>0</enable_wind>
        <kinematic>0</kinematic>
      </link>
      <joint name='left_rear_wheel' type='revolute'>
        <pose relative_to='base_footprint'>-0.219194 0.19 0.108054 0 -0.142 0</pose>
        <parent>base_footprint</parent>
        <child>left_rear_wheel_link</child>
        <axis>
          <xyz>0 1 0</xyz>
          <limit>
            <lower>-1e+16</lower>
            <upper>1e+16</upper>
          </limit>
          <dynamics>
            <spring_reference>0</spring_reference>
            <spring_stiffness>0</spring_stiffness>
          </dynamics>
        </axis>
      </joint>
      <link name='left_rear_wheel_link'>
        <pose relative_to='left_rear_wheel'>0 0 0 0 -0 0</pose>
        <inertial>
          <pose>0 0 0 1.5708 -0 0</pose>
          <mass>3</mass>
          <inertia>
            <ixx>0.009013</ixx>
            <ixy>0</ixy>
            <ixz>0</ixz>
            <iyy>0.009013</iyy>
            <iyz>0</iyz>
            <izz>0.0159135</izz>
          </inertia>
        </inertial>
        <collision name='left_rear_wheel_link_collision'>
          <pose>0 0 0 1.5708 -0 0</pose>
          <geometry>
            <cylinder>
              <length>0.065</length>
              <radius>0.103</radius>
            </cylinder>
          </geometry>
          <surface>
            <contact>
              <ode>
                <kp>1e+07</kp>
                <kd>1</kd>
              </ode>
            </contact>
            <friction>
              <ode>
                <mu>1</mu>
                <mu2>1</mu2>
                <fdir1>1 0 0</fdir1>
              </ode>
              <torsional>
                <ode/>
              </torsional>
            </friction>
            <bounce/>
          </surface>
          <max_contacts>10</max_contacts>
        </collision>
        <visual name='left_rear_wheel_link_visual'>
          <pose>0 0 0 0 -0 0</pose>
          <geometry>
            <mesh>
              <scale>1 1 1</scale>
              <uri>/root/catkin_ws/src/pluto_robot/pluto_description/meshes/pluto_wheel.stl</uri>
            </mesh>
          </geometry>
          <material>
            <script>
              <name>Gazebo/DarkGrey</name>
              <uri>file://media/materials/scripts/gazebo.material</uri>
            </script>
          </material>
        </visual>
        <self_collide>0</self_collide>
        <enable_wind>0</enable_wind>
        <kinematic>0</kinematic>
      </link>
      <joint name='right_rear_wheel' type='revolute'>
        <pose relative_to='base_footprint'>-0.219194 -0.19 0.108054 0 -0.142 0</pose>
        <parent>base_footprint</parent>
        <child>right_rear_wheel_link</child>
        <axis>
          <xyz>0 1 0</xyz>
          <limit>
            <lower>-1e+16</lower>
            <upper>1e+16</upper>
          </limit>
          <dynamics>
            <spring_reference>0</spring_reference>
            <spring_stiffness>0</spring_stiffness>
          </dynamics>
        </axis>
      </joint>
      <link name='right_rear_wheel_link'>
        <pose relative_to='right_rear_wheel'>0 0 0 0 -0 0</pose>
        <inertial>
          <pose>0 0 0 1.5708 -0 0</pose>
          <mass>3</mass>
          <inertia>
            <ixx>0.009013</ixx>
            <ixy>0</ixy>
            <ixz>0</ixz>
            <iyy>0.009013</iyy>
            <iyz>0</iyz>
            <izz>0.0159135</izz>
          </inertia>
        </inertial>
        <collision name='right_rear_wheel_link_collision'>
          <pose>0 0 0 1.5708 -0 0</pose>
          <geometry>
            <cylinder>
              <length>0.065</length>
              <radius>0.103</radius>
            </cylinder>
          </geometry>
          <surface>
            <contact>
              <ode>
                <kp>1e+07</kp>
                <kd>1</kd>
              </ode>
            </contact>
            <friction>
              <ode>
                <mu>1</mu>
                <mu2>1</mu2>
                <fdir1>1 0 0</fdir1>
              </ode>
              <torsional>
                <ode/>
              </torsional>
            </friction>
            <bounce/>
          </surface>
          <max_contacts>10</max_contacts>
        </collision>
        <visual name='right_rear_wheel_link_visual'>
          <pose>0 0 0 0 -0 0</pose>
          <geometry>
            <mesh>
              <scale>1 1 1</scale>
              <uri>/root/catkin_ws/src/pluto_robot/pluto_description/meshes/pluto_wheel.stl</uri>
            </mesh>
          </geometry>
          <material>
            <script>
              <name>Gazebo/DarkGrey</name>
              <uri>file://media/materials/scripts/gazebo.material</uri>
            </script>
          </material>
        </visual>
        <self_collide>0</self_collide>
        <enable_wind>0</enable_wind>
        <kinematic>0</kinematic>
      </link>
      <joint name='virtual_left_to_base_joint' type='revolute'>
        <pose relative_to='base_footprint'>0.108621 0.175 0.10441 0 -0 0</pose>
        <parent>base_footprint</parent>
        <child>virtual_axis_left</child>
        <axis>
          <xyz>0 1 0</xyz>
          <limit>
            <lower>-0.4</lower>
            <upper>0.4</upper>
            <effort>1000</effort>
            <velocity>10</velocity>
          </limit>
          <dynamics>
            <spring_reference>0</spring_reference>
            <spring_stiffness>0</spring_stiffness>
          </dynamics>
        </axis>
      </joint>
      <link name='virtual_axis_left'>
        <pose relative_to='virtual_left_to_base_joint'>0 0 0 0 -0 0</pose>
        <inertial>
          <pose>0 0 0 0 -0 0</pose>
          <mass>0.1</mass>
          <inertia>
            <ixx>8.08333e-05</ixx>
            <ixy>0</ixy>
            <ixz>0</ixz>
            <iyy>0.000657133</iyy>
            <iyz>0</iyz>
            <izz>0.000602966</izz>
          </inertia>
        </inertial>
        <collision name='virtual_axis_left_collision'>
          <pose>0 0 0 0 0 -3.14159</pose>
          <geometry>
            <mesh>
              <scale>1 1 1</scale>
              <uri>/root/catkin_ws/src/pluto_robot/pluto_description/meshes/pluto_lever_collision.stl</uri>
            </mesh>
          </geometry>
          <surface>
            <contact>
              <ode/>
            </contact>
            <friction>
              <ode/>
              <torsional>
                <ode/>
              </torsional>
            </friction>
            <bounce/>
          </surface>
          <max_contacts>10</max_contacts>
        </collision>
        <visual name='virtual_axis_left_visual'>
          <pose>0 0 0 0 0 -3.14159</pose>
          <geometry>
            <mesh>
              <scale>1 1 1</scale>
              <uri>/root/catkin_ws/src/pluto_robot/pluto_description/meshes/pluto_lever.stl</uri>
            </mesh>
          </geometry>
          <material>
            <script>
              <name>Gazebo/GreyTransparent</name>
              <uri>file://media/materials/scripts/gazebo.material</uri>
            </script>
          </material>
        </visual>
        <visual name='virtual_axis_left_fixed_joint_lump__imu_left_visual_1'>
          <pose>0 0 0.2 0 -0 0</pose>
          <geometry>
            <box>
              <size>0.06 0.06 0.02</size>
            </box>
          </geometry>
        </visual>
        <self_collide>0</self_collide>
        <enable_wind>0</enable_wind>
        <kinematic>0</kinematic>
      </link>
      <joint name='left_front_wheel' type='revolute'>
        <pose relative_to='virtual_axis_left'>0.1075 0.095 0 0 -0 0</pose>
        <parent>virtual_axis_left</parent>
        <child>left_front_wheel_link</child>
        <axis>
          <xyz>0 1 0</xyz>
          <limit>
            <lower>-1e+16</lower>
            <upper>1e+16</upper>
          </limit>
          <dynamics>
            <spring_reference>0</spring_reference>
            <spring_stiffness>0</spring_stiffness>
          </dynamics>
        </axis>
      </joint>
      <link name='left_front_wheel_link'>
        <pose relative_to='left_front_wheel'>0 0 0 0 -0 0</pose>
        <inertial>
          <pose>0 0 0 1.5708 -0 0</pose>
          <mass>3</mass>
          <inertia>
            <ixx>0.009013</ixx>
            <ixy>0</ixy>
            <ixz>0</ixz>
            <iyy>0.009013</iyy>
            <iyz>0</iyz>
            <izz>0.0159135</izz>
          </inertia>
        </inertial>
        <collision name='left_front_wheel_link_collision'>
          <pose>0 0 0 1.5708 -0 0</pose>
          <geometry>
            <cylinder>
              <length>0.065</length>
              <radius>0.103</radius>
            </cylinder>
          </geometry>
          <surface>
            <contact>
              <ode>
                <kp>1e+07</kp>
                <kd>1</kd>
              </ode>
            </contact>
            <friction>
              <ode>
                <mu>1</mu>
                <mu2>1</mu2>
                <fdir1>1 0 0</fdir1>
              </ode>
              <torsional>
                <ode/>
              </torsional>
            </friction>
            <bounce/>
          </surface>
          <max_contacts>10</max_contacts>
        </collision>
        <visual name='left_front_wheel_link_visual'>
          <pose>0 0 0 0 -0 0</pose>
          <geometry>
            <mesh>
              <scale>1 1 1</scale>
              <uri>/root/catkin_ws/src/pluto_robot/pluto_description/meshes/pluto_wheel.stl</uri>
            </mesh>
          </geometry>
          <material>
            <script>
              <name>Gazebo/DarkGrey</name>
              <uri>file://media/materials/scripts/gazebo.material</uri>
            </script>
          </material>
        </visual>
        <self_collide>0</self_collide>
        <enable_wind>0</enable_wind>
        <kinematic>0</kinematic>
      </link>
      <joint name='left_middle_wheel' type='revolute'>
        <pose relative_to='virtual_axis_left'>-0.1075 0.095 0 0 -0 0</pose>
        <parent>virtual_axis_left</parent>
        <child>left_middle_wheel_link</child>
        <axis>
          <xyz>0 1 0</xyz>
          <limit>
            <lower>-1e+16</lower>
            <upper>1e+16</upper>
          </limit>
          <dynamics>
            <spring_reference>0</spring_reference>
            <spring_stiffness>0</spring_stiffness>
          </dynamics>
        </axis>
      </joint>
      <link name='left_middle_wheel_link'>
        <pose relative_to='left_middle_wheel'>0 0 0 0 -0 0</pose>
        <inertial>
          <pose>0 0 0 1.5708 -0 0</pose>
          <mass>3</mass>
          <inertia>
            <ixx>0.009013</ixx>
            <ixy>0</ixy>
            <ixz>0</ixz>
            <iyy>0.009013</iyy>
            <iyz>0</iyz>
            <izz>0.0159135</izz>
          </inertia>
        </inertial>
        <collision name='left_middle_wheel_link_collision'>
          <pose>0 0 0 1.5708 -0 0</pose>
          <geometry>
            <cylinder>
              <length>0.065</length>
              <radius>0.103</radius>
            </cylinder>
          </geometry>
          <surface>
            <contact>
              <ode>
                <kp>1e+07</kp>
                <kd>1</kd>
              </ode>
            </contact>
            <friction>
              <ode>
                <mu>1</mu>
                <mu2>1</mu2>
                <fdir1>1 0 0</fdir1>
              </ode>
              <torsional>
                <ode/>
              </torsional>
            </friction>
            <bounce/>
          </surface>
          <max_contacts>10</max_contacts>
        </collision>
        <visual name='left_middle_wheel_link_visual'>
          <pose>0 0 0 0 -0 0</pose>
          <geometry>
            <mesh>
              <scale>1 1 1</scale>
              <uri>/root/catkin_ws/src/pluto_robot/pluto_description/meshes/pluto_wheel.stl</uri>
            </mesh>
          </geometry>
          <material>
            <script>
              <name>Gazebo/DarkGrey</name>
              <uri>file://media/materials/scripts/gazebo.material</uri>
            </script>
          </material>
        </visual>
        <self_collide>0</self_collide>
        <enable_wind>0</enable_wind>
        <kinematic>0</kinematic>
      </link>
      <joint name='virtual_right_to_base_joint' type='revolute'>
        <pose relative_to='base_footprint'>0.108621 -0.175 0.10441 0 -0 0</pose>
        <parent>base_footprint</parent>
        <child>virtual_axis_right</child>
        <axis>
          <xyz>0 1 0</xyz>
          <limit>
            <lower>-0.4</lower>
            <upper>0.4</upper>
            <effort>1000</effort>
            <velocity>10</velocity>
          </limit>
          <dynamics>
            <spring_reference>0</spring_reference>
            <spring_stiffness>0</spring_stiffness>
          </dynamics>
        </axis>
      </joint>
      <link name='virtual_axis_right'>
        <pose relative_to='virtual_right_to_base_joint'>0 0 0 0 -0 0</pose>
        <inertial>
          <pose>0 0 0 0 -0 0</pose>
          <mass>0.1</mass>
          <inertia>
            <ixx>8.08333e-05</ixx>
            <ixy>0</ixy>
            <ixz>0</ixz>
            <iyy>0.000657133</iyy>
            <iyz>0</iyz>
            <izz>0.000602966</izz>
          </inertia>
        </inertial>
        <collision name='virtual_axis_right_collision'>
          <pose>0 0 0 0 -0 0</pose>
          <geometry>
            <mesh>
              <scale>1 1 1</scale>
              <uri>/root/catkin_ws/src/pluto_robot/pluto_description/meshes/pluto_lever_collision.stl</uri>
            </mesh>
          </geometry>
          <surface>
            <contact>
              <ode/>
            </contact>
            <friction>
              <ode/>
              <torsional>
                <ode/>
              </torsional>
            </friction>
            <bounce/>
          </surface>
          <max_contacts>10</max_contacts>
        </collision>
        <visual name='virtual_axis_right_visual'>
          <pose>0 0 0 0 -0 0</pose>
          <geometry>
            <mesh>
              <scale>1 1 1</scale>
              <uri>/root/catkin_ws/src/pluto_robot/pluto_description/meshes/pluto_lever.stl</uri>
            </mesh>
          </geometry>
          <material>
            <script>
              <name>Gazebo/GreyTransparent</name>
              <uri>file://media/materials/scripts/gazebo.material</uri>
            </script>
          </material>
        </visual>
        <visual name='virtual_axis_right_fixed_joint_lump__imu_right_visual_1'>
          <pose>0 0 0.2 0 -0 0</pose>
          <geometry>
            <box>
              <size>0.06 0.06 0.02</size>
            </box>
          </geometry>
        </visual>
        <self_collide>0</self_collide>
        <enable_wind>0</enable_wind>
        <kinematic>0</kinematic>
      </link>
      <joint name='right_front_wheel' type='revolute'>
        <pose relative_to='virtual_axis_right'>0.1075 -0.095 0 0 -0 0</pose>
        <parent>virtual_axis_right</parent>
        <child>right_front_wheel_link</child>
        <axis>
          <xyz>0 1 0</xyz>
          <limit>
            <lower>-1e+16</lower>
            <upper>1e+16</upper>
          </limit>
          <dynamics>
            <spring_reference>0</spring_reference>
            <spring_stiffness>0</spring_stiffness>
          </dynamics>
        </axis>
      </joint>
      <link name='right_front_wheel_link'>
        <pose relative_to='right_front_wheel'>0 0 0 0 -0 0</pose>
        <inertial>
          <pose>0 0 0 1.5708 -0 0</pose>
          <mass>3</mass>
          <inertia>
            <ixx>0.009013</ixx>
            <ixy>0</ixy>
            <ixz>0</ixz>
            <iyy>0.009013</iyy>
            <iyz>0</iyz>
            <izz>0.0159135</izz>
          </inertia>
        </inertial>
        <collision name='right_front_wheel_link_collision'>
          <pose>0 0 0 1.5708 -0 0</pose>
          <geometry>
            <cylinder>
              <length>0.065</length>
              <radius>0.103</radius>
            </cylinder>
          </geometry>
          <surface>
            <contact>
              <ode>
                <kp>1e+07</kp>
                <kd>1</kd>
              </ode>
            </contact>
            <friction>
              <ode>
                <mu>1</mu>
                <mu2>1</mu2>
                <fdir1>1 0 0</fdir1>
              </ode>
              <torsional>
                <ode/>
              </torsional>
            </friction>
            <bounce/>
          </surface>
          <max_contacts>10</max_contacts>
        </collision>
        <visual name='right_front_wheel_link_visual'>
          <pose>0 0 0 0 -0 0</pose>
          <geometry>
            <mesh>
              <scale>1 1 1</scale>
              <uri>/root/catkin_ws/src/pluto_robot/pluto_description/meshes/pluto_wheel.stl</uri>
            </mesh>
          </geometry>
          <material>
            <script>
              <name>Gazebo/DarkGrey</name>
              <uri>file://media/materials/scripts/gazebo.material</uri>
            </script>
          </material>
        </visual>
        <self_collide>0</self_collide>
        <enable_wind>0</enable_wind>
        <kinematic>0</kinematic>
      </link>
      <joint name='right_middle_wheel' type='revolute'>
        <pose relative_to='virtual_axis_right'>-0.1075 -0.095 0 0 -0 0</pose>
        <parent>virtual_axis_right</parent>
        <child>right_middle_wheel_link</child>
        <axis>
          <xyz>0 1 0</xyz>
          <limit>
            <lower>-1e+16</lower>
            <upper>1e+16</upper>
          </limit>
          <dynamics>
            <spring_reference>0</spring_reference>
            <spring_stiffness>0</spring_stiffness>
          </dynamics>
        </axis>
      </joint>
      <link name='right_middle_wheel_link'>
        <pose relative_to='right_middle_wheel'>0 0 0 0 -0 0</pose>
        <inertial>
          <pose>0 0 0 1.5708 -0 0</pose>
          <mass>3</mass>
          <inertia>
            <ixx>0.009013</ixx>
            <ixy>0</ixy>
            <ixz>0</ixz>
            <iyy>0.009013</iyy>
            <iyz>0</iyz>
            <izz>0.0159135</izz>
          </inertia>
        </inertial>
        <collision name='right_middle_wheel_link_collision'>
          <pose>0 0 0 1.5708 -0 0</pose>
          <geometry>
            <cylinder>
              <length>0.065</length>
              <radius>0.103</radius>
            </cylinder>
          </geometry>
          <surface>
            <contact>
              <ode>
                <kp>1e+07</kp>
                <kd>1</kd>
              </ode>
            </contact>
            <friction>
              <ode>
                <mu>1</mu>
                <mu2>1</mu2>
                <fdir1>1 0 0</fdir1>
              </ode>
              <torsional>
                <ode/>
              </torsional>
            </friction>
            <bounce/>
          </surface>
          <max_contacts>10</max_contacts>
        </collision>
        <visual name='right_middle_wheel_link_visual'>
          <pose>0 0 0 0 -0 0</pose>
          <geometry>
            <mesh>
              <scale>1 1 1</scale>
              <uri>/root/catkin_ws/src/pluto_robot/pluto_description/meshes/pluto_wheel.stl</uri>
            </mesh>
          </geometry>
          <material>
            <script>
              <name>Gazebo/DarkGrey</name>
              <uri>file://media/materials/scripts/gazebo.material</uri>
            </script>
          </material>
        </visual>
        <self_collide>0</self_collide>
        <enable_wind>0</enable_wind>
        <kinematic>0</kinematic>
      </link>
      <plugin name='imu_controller' filename='libgazebo_ros_imu.so'>
        <alwaysOn>1</alwaysOn>
        <updateRate>100.0</updateRate>
        <topicName>imu/data</topicName>
        <serviceName>/default_imu</serviceName>
        <gaussianNoise>2.8900000000000004e-08</gaussianNoise>
        <xyzOffsets>0 0 0</xyzOffsets>
        <rpyOffsets>0 0 0</rpyOffsets>
        <ns0:position name='imu_position'/>
        <robotNamespace>/</robotNamespace>
        <bodyName>base_footprint</bodyName>
        <xyzOffset>0.0215035 0 0.127312</xyzOffset>
        <rpyOffset>2.9996 5.19844e-07 1.5708</rpyOffset>
        <ignition::corrected_offsets>1</ignition::corrected_offsets>
      </plugin>
      <plugin name='novatel_gps_sim' filename='libhector_gazebo_ros_gps.so'>
        <frameId>odom_combined</frameId>
        <alwaysOn>1</alwaysOn>
        <updateRate>10.0</updateRate>
        <bodyName>base_footprint</bodyName>
        <topicName>gps/fix</topicName>
        <velocityTopicName>gps/fix_velocity</velocityTopicName>
        <drift>1.0 1.0 1.0</drift>
        <gaussianNoise>0.1 0.1 0.1</gaussianNoise>
        <velocityDrift>0 0 0</velocityDrift>
        <velocityGaussianNoise>0.1 0.1 0.1</velocityGaussianNoise>
        <robotNamespace>/</robotNamespace>
      </plugin>
      <plugin name='base_footprint_controller' filename='libgazebo_ros_p3d.so'>
        <alwaysOn>1</alwaysOn>
        <updateRate>30.0</updateRate>
        <bodyName>base_footprint</bodyName>
        <topicName>gazebo_odom</topicName>
        <gaussianNoise>1.0e-40</gaussianNoise>
        <frameName>map</frameName>
        <ns0:position name='base_footprint_p3d_position_iface'/>
        <robotNamespace>/</robotNamespace>
      </plugin>
      <plugin name='gazebo_ros_control' filename='libgazebo_ros_control.so'>
        <robotNamespace>/</robotNamespace>
      </plugin>
      <frame name='imu_center_to_base_joint' attached_to='base_link'>
        <pose>0.011 0 -0.075 -3.14159 -0 1.5708</pose>
      </frame>
      <frame name='imu_center' attached_to='imu_center_to_base_joint'/>
      <frame name='velodyne_to_base_joint' attached_to='base_link'>
        <pose>0.2895 0 0.157905 0 -0 0</pose>
      </frame>
      <frame name='velodyne' attached_to='velodyne_to_base_joint'/>
      <frame name='base_footprint_to_base_joint' attached_to='base_footprint'>
        <pose>0 0 0.2 0 -0.142 0</pose>
      </frame>
      <frame name='base_link' attached_to='base_footprint_to_base_joint'/>
      <frame name='imu_left_to_base_joint' attached_to='virtual_axis_left'>
        <pose>0 0 0.2 0 -0 0</pose>
      </frame>
      <frame name='imu_left' attached_to='imu_left_to_base_joint'/>
      <frame name='imu_right_to_base_joint' attached_to='virtual_axis_right'>
        <pose>0 0 0.2 0 -0 0</pose>
      </frame>
      <frame name='imu_right' attached_to='imu_right_to_base_joint'/>
      <pose>0 0 0 0 0 -1.55</pose>
    </model>
    <state world_name='default'>
      <sim_time>110 472000000</sim_time>
      <real_time>4 450238842</real_time>
      <wall_time>1739952408 116559363</wall_time>
      <iterations>4305</iterations>
      <model name='botanical_garden'>
        <pose>0 0 0 0 -0 2.60054</pose>
        <scale>1 1 1</scale>
        <link name='body'>
          <pose>0 0 0 0 -0 2.60054</pose>
          <velocity>0 0 0 0 -0 0</velocity>
          <acceleration>0 0 0 0 -0 0</acceleration>
          <wrench>0 0 0 0 -0 0</wrench>
        </link>
      </model>
      <model name='pluto'>
        <pose>-0.017464 -0.087715 -1.31417 0.002047 -0.00702 -1.77426</pose>
        <scale>1 1 1</scale>
        <link name='base_footprint'>
          <pose>-0.017464 -0.087715 -1.31417 0.002047 -0.00702 -1.77426</pose>
          <velocity>0.000633 -0.008854 -0.000753 -0.005902 -0.010886 -0.013259</velocity>
          <acceleration>0.003384 -0.009299 -0.007277 -0.18053 -0.926931 0.089636</acceleration>
          <wrench>0.135346 -0.371943 -0.291083 0 -0 0</wrench>
        </link>
        <link name='left_front_wheel_link'>
          <pose>0.203089 -0.353301 -1.20662 2.75735 -1.51906 1.74983</pose>
          <velocity>-0.004792 -0.010921 -0.000284 -0.001281 0.003051 -0.014396</velocity>
          <acceleration>0.037125 -0.082172 -0.786807 -2.47648 -1.20888 2.75865</acceleration>
          <wrench>0.111375 -0.246516 -2.36042 0 -0 0</wrench>
        </link>
        <link name='left_middle_wheel_link'>
          <pose>0.246733 -0.142756 -1.20849 3.12797 0.329605 1.36154</pose>
          <velocity>-0.001938 -0.011112 -0.000827 0.107971 -0.01905 -0.00963</velocity>
          <acceleration>0.029947 -0.048852 0.007918 0.330585 0.541497 -0.091244</acceleration>
          <wrench>0.089842 -0.146556 0.023753 0 -0 0</wrench>
        </link>
        <link name='left_rear_wheel_link'>
          <pose>0.212844 0.08935 -1.20727 0.00213 0.279877 -1.77366</pose>
          <velocity>0.001866 -0.011291 0.000743 -0.00593 -0.010963 -0.013312</velocity>
          <acceleration>0.037129 -0.030548 0.035684 -0.142302 -0.552345 -0.026321</acceleration>
          <wrench>0.111388 -0.091643 0.107051 0 -0 0</wrench>
        </link>
        <link name='right_front_wheel_link'>
          <pose>-0.32561 -0.244061 -1.20908 3.14092 -1.53027 1.36779</pose>
          <velocity>-0.003327 -0.004371 -8.3e-05 0.000682 0.012782 -0.012705</velocity>
          <acceleration>0.025806 0.031721 0.318198 -2.57436 -0.435552 3.01085</acceleration>
          <wrench>0.077418 0.095164 0.954595 0 -0 0</wrench>
        </link>
        <link name='right_middle_wheel_link'>
          <pose>-0.282088 -0.033486 -1.20959 3.14007 0.058654 1.36705</pose>
          <velocity>-0.000884 -0.005243 -0.000716 0.048046 -0.007443 -0.00929</velocity>
          <acceleration>0.029068 -0.001715 -0.010164 0.051818 0.491727 -0.003494</acceleration>
          <wrench>0.087204 -0.005144 -0.030491 0 -0 0</wrench>
        </link>
        <link name='right_rear_wheel_link'>
          <pose>-0.159332 0.166146 -1.20805 0.001709 -0.462286 -1.77514</pose>
          <velocity>0.005636 -0.007887 -0.003118 0.006958 -0.112501 -0.005182</velocity>
          <acceleration>-0.107416 0.037464 -0.101444 -1.80983 1.08993 2.93724</acceleration>
          <wrench>-0.322247 0.112393 -0.304333 0 -0 0</wrench>
        </link>
        <link name='virtual_axis_left'>
          <pose>0.131953 -0.228731 -1.20856 0.019712 -0.00272 -1.77558</pose>
          <velocity>-0.002912 -0.009911 0.0012 -0.004577 -0.009551 -0.014853</velocity>
          <acceleration>0.027306 -0.05653 0.022887 -2.75903 -1.21627 0.36124</acceleration>
          <wrench>0.002731 -0.005653 0.002289 0 -0 0</wrench>
        </link>
        <link name='virtual_axis_right'>
          <pose>-0.210873 -0.157965 -1.20937 0.002709 -0.003164 -1.77419</pose>
          <velocity>-0.001313 -0.005657 -0.002522 -0.003554 -0.016833 -0.013015</velocity>
          <acceleration>0.032152 -0.026563 -0.056691 2.66699 -0.668182 3.11216</acceleration>
          <wrench>0.003215 -0.002656 -0.005669 0 -0 0</wrench>
        </link>
      </model>
    </state>
    <gui fullscreen='0'>
      <camera name='user_camera'>
        <pose>1.99843 4.59307 37.5533 3.14159 1.57079 3.14159</pose>
        <view_controller>orbit</view_controller>
        <projection_type>perspective</projection_type>
      </camera>
    </gui>
  </world>
</sdf>
